<mujoco model="Asimov">
  <compiler angle="radian" meshdir="../assets/meshes"/>
  <visual>
    <global offwidth="1920" offheight="1080"/>
  </visual>

<default>
  <joint frictionloss="0.1"/>  <!-- All joints get this by default -->
  
  <default class="motor">
    <joint damping="0.5"/> 
  </default>
  
  <default class="visual">
    <geom material="visual_grey" contype="0" conaffinity="0" group="2"/>
  </default>
  
  <default class="collision">
    <geom material="collision_grey" condim="3" contype="0" conaffinity="1" group="1"/>
  </default>
</default>



  <asset>
    <!-- Add these material definitions -->
    <material name="visual_grey" rgba="0.7 0.7 0.7 1.0" />
    <material name="collision_grey" rgba="0.5 0.5 0.5 0.5" />
    <texture type="skybox" builtin="flat" rgb1="0 0 0" rgb2="0 0 0" width="512" height="3072"/>
    <texture type="2d" name="groundplane" builtin="checker" mark="edge" rgb1="0.2 0.3 0.4" rgb2="0.1 0.2 0.3" markrgb="0.8 0.8 0.8" width="300" height="300"/>
    <material name="groundplane" texture="groundplane" texuniform="true" texrepeat="5 5" reflectance="0.2"/>
    <texture type="skybox" builtin="gradient" rgb1="0.3 0.5 0.7" rgb2="0 0 0" width="512" height="512"/>
    <texture name="texplane" type="2d" builtin="checker" rgb1=".2 .3 .4" rgb2=".1 0.15 0.2" width="512" height="512" mark="cross" markrgb=".8 .8 .8"/>
    <material name="material" rgba="0.75294 0.75294 0.75294 1" />
    <material name="collision_material" rgba="1.0 0.28 0.1 0.9" />
    <mesh name="pelvis_link.STL" file="pelvis_link.STL" />
    <mesh name="left_hip_pitch_link.STL" file="left_hip_pitch_link.STL" />
    <mesh name="left_hip_roll_link.STL" file="left_hip_roll_link.STL" />
    <mesh name="left_hip_yaw_link.STL" file="left_hip_yaw_link.STL" />
    <mesh name="left_knee_link.STL" file="left_knee_link.STL" />
    <mesh name="left_ankle_pitch_link.STL" file="left_ankle_pitch_link.STL" />
    <mesh name="left_ankle_roll_link.STL" file="left_ankle_roll_link.STL" />
    <mesh name="left_toe_link.STL" file="left_toe_link.STL" />
    <mesh name="right_hip_pitch_link.STL" file="right_hip_pitch_link.STL" />
    <mesh name="right_hip_roll_link.STL" file="right_hip_roll_link.STL" />
    <mesh name="right_hip_yaw_link.STL" file="right_hip_yaw_link.STL" />
    <mesh name="right_knee_link.STL" file="right_knee_link.STL" />
    <mesh name="right_ankle_pitch_link.STL" file="right_ankle_pitch_link.STL" />
    <mesh name="right_ankle_roll_link.STL" file="right_ankle_roll_link.STL" />
    <mesh name="right_toe_link.STL" file="right_toe_link.STL" />
  </asset>

  <worldbody>
    <light pos="1 0 3.5" dir="0 0 -1" directional="true"/>
    <geom name="floor" size="0 0 0.05" type="plane" material="groundplane"/>
    <light directional="true" diffuse=".4 .4 .4" specular="0.1 0.1 0.1" pos="0 0 5.0" dir="0 0 -1" castshadow="false" />
    <light directional="true" diffuse=".6 .6 .6" specular="0.2 0.2 0.2" pos="0 0 4" dir="0 0 -1" />

    <body name="pelvis_link" pos="0.00000000 0.00000000 0.91572740" quat="1 0 0 0 ">  
    <!-- <body name="pelvis_link" pos="0 0 0.91572740" quat="0.92388 -0.3827 0 0"> -->

    <!-- <body name="pelvis_link" pos="0 0 0.91572740" quat="0.9239 0 0.3827 0"> -->
      <inertial pos="-0.00071228 -3.4719E-07 -0.073826" quat="1.0 0.0 0.0 0.0" mass="3.3125" diaginertia="0.0033117 0.0028238 0.003564" />
      <joint name="floating_base_joint" type="free" limited="false" actuatorfrclimited="false"/>
      <geom name="pelvis_link_collision" pos="0 0 0" quat="1.0 0.0 0.0 0.0" type="mesh" mesh="pelvis_link.STL"/>
      <geom name="pelvis_link_visual" pos="0 0 0" quat="1.0 0.0 0.0 0.0" type="mesh" mesh="pelvis_link.STL" class="visual" />
      <site name="imu_in_pelvis" size="0.01" pos="0.04525 0 -0.08339"/>

      <body name="left_hip_pitch_link" pos="0 0.056569 -0.10543" quat="1.0 0.0 0.0 0.0">

        <joint name="left_hip_pitch_joint" type="hinge" ref="0.0" class="motor" range="-2.094395 1" axis="0 0.70711 -0.70711" armature="0.0652"/>
        <inertial pos="0.00329 0.045581 -0.045581" quat="1.0 0.0 0.0 0.0" mass="0.92565" diaginertia="0.00053984 0.00066418 0.00066419" />
        <geom name="left_hip_pitch_link_collision" pos="0 0 0" quat="1.0 0.0 0.0 0.0" type="mesh" mesh="left_hip_pitch_link.STL" class="collision" />
        <geom name="left_hip_pitch_link_visual" pos="0 0 0" quat="1.0 0.0 0.0 0.0" type="mesh" mesh="left_hip_pitch_link.STL" class="visual" />

        <body name="left_hip_roll_link" pos="0 0.051265 -0.051265" quat="1.0 0.0 0.0 0.0">
          <joint name="left_hip_roll_joint" type="hinge" ref="0.0" class="motor" range="-0.785398 0.785398" axis="1 0 0" armature="0.100"/>

          <inertial pos="0.01525 -0.00017964 -0.061059" quat="1.0 0.0 0.0 0.0" mass="0.83528" diaginertia="0.00054401 0.00063585 0.00038113" />
          <geom name="left_hip_roll_link_collision" pos="0 0 0" quat="1.0 0.0 0.0 0.0" type="mesh" mesh="left_hip_roll_link.STL" class="collision" />
          <geom name="left_hip_roll_link_visual" pos="0 0 0" quat="1.0 0.0 0.0 0.0"  type="mesh" mesh="left_hip_roll_link.STL" class="visual" />
          <body name="left_hip_yaw_link" pos="0 0 -0.09275" quat="1.0 0.0 0.0 0.0">

            <joint name="left_hip_yaw_joint" type="hinge" ref="0.0" class="motor" range="-0.785398 0.785398" axis="0 0 -1" armature="0.0343"/>
            <inertial pos="7.0761E-05 0.00031363 -0.11496" quat="1.0 0.0 0.0 0.0" mass="1.2782" diaginertia="0.0024302 0.0025065 0.0007566" />
            <geom name="left_hip_yaw_link_collision" pos="0 0 0" quat="1.0 0.0 0.0 0.0" type="mesh" mesh="left_hip_yaw_link.STL" class="collision" />
            <geom name="left_hip_yaw_link_visual" pos="0 0 0" quat="1.0 0.0 0.0 0.0"  type="mesh" mesh="left_hip_yaw_link.STL" class="visual" />
          
            <body name="left_knee_link" pos="0 0 -0.15489" quat="1.0 0.0 0.0 0.0">
              <joint name="left_knee_joint" type="hinge" ref="0.0" class="motor" range="0 1.5" axis="0 1 0" armature="0.0330"/>
              <inertial pos="-0.0025212 0.00051084 -0.10659" quat="1.0 0.0 0.0 0.0" mass="2.2481" diaginertia="0.0093797 0.0095623 0.0023403" />
              <geom name="left_knee_link_collision" pos="0 0 0" quat="1.0 0.0 0.0 0.0" type="mesh" mesh="left_knee_link.STL" class="collision" />
              <geom name="left_knee_link_visual" pos="0 0 0" quat="1.0 0.0 0.0 0.0"  type="mesh" mesh="left_knee_link.STL" class="visual" />
              <body name="left_ankle_pitch_link" pos="0 0 -0.29466" quat="1.0 0.0 0.0 0.0">


                <joint name="left_ankle_pitch_joint" type="hinge" ref="0.0" class="motor" range="-0.349066 0.5" axis="0 1 0" armature="0.0236"/>
                <inertial pos="-0.0011784 -2.4418E-08 -0.0061736" quat="1.0 0.0 0.0 0.0" mass="0.27369" diaginertia="6.4443e-05 8.1172e-05 4.7493e-05" />
                <geom name="left_ankle_pitch_link_collision" pos="0 0 0" quat="1.0 0.0 0.0 0.0" type="mesh" mesh="left_ankle_pitch_link.STL" class="collision" />
                <geom name="left_ankle_pitch_link_visual" pos="0 0 0" quat="1.0 0.0 0.0 0.0"  type="mesh" mesh="left_ankle_pitch_link.STL" class="visual" />
                <body name="left_ankle_roll_link" pos="-0.0015 0 -0.01" quat="1.0 0.0 0.0 0.0">

                  <joint name="left_ankle_roll_joint" type="hinge" ref="0.0" class="motor" range="-0.1 0.1" axis="-1 0 0" armature="0.0236"/>
                  <inertial pos="0.081381 -0.00033806 -0.015509" quat="1.0 0.0 0.0 0.0" mass="0.61291" diaginertia="0.00031968 0.00045036 0.00070504" />
                  <geom name="left_ankle_roll_link_collision" pos="0 0 0" quat="1.0 0.0 0.0 0.0" type="mesh" mesh="left_ankle_roll_link.STL" class="collision" />
                  <geom name="left_ankle_roll_link_visual" pos="0 0 0" quat="1.0 0.0 0.0 0.0"  type="mesh" mesh="left_ankle_roll_link.STL" class="visual" />
                  <body name="left_toe_link" pos="0.10253 -0.0043664 -0.0067324" quat="1.0 0.0 0.0 0.0">
                    <inertial pos="0.0320167773761624 0.000718248511968056 -0.0141312773022902" quat="1.0 0.0 0.0 0.0" mass="0.112221237946844" diaginertia="5.5351925218088e-05 3.65130809524718e-05 8.54029969529202e-05" />
                    <geom name="left_toe_link_collision" pos="0 0 0" quat="1.0 0.0 0.0 0.0" type="mesh" mesh="left_toe_link.STL" class="collision" />
                    <geom name="left_toe_link_visual" pos="0 0 0" quat="1.0 0.0 0.0 0.0"  type="mesh" mesh="left_toe_link.STL" class="visual" />
                    <site name="left_foot" pos="0.04 0 -0.025"/>
                  </body>
                </body>
              </body>
            </body>
          </body>
        </body>
      </body>
      <body name="right_hip_pitch_link" pos="0 -0.056569 -0.10543" quat="1.0 0.0 0.0 0.0">
        <inertial pos="0.0032901 -0.045581 -0.045581" quat="1.0 0.0 0.0 0.0" mass="0.92565" diaginertia="0.00053984 0.00066418 0.00066418" />
        <joint name="right_hip_pitch_joint" type="hinge" ref="0.0" class="motor" range="-1 2.094395" axis="0 -0.70711 -0.70711" armature="0.0652"/>
        <geom name="right_hip_pitch_link_collision" pos="0 0 0" quat="1.0 0.0 0.0 0.0" type="mesh" mesh="right_hip_pitch_link.STL" class="collision" />
        <geom name="right_hip_pitch_link_visual" pos="0 0 0" quat="1.0 0.0 0.0 0.0"  type="mesh" mesh="right_hip_pitch_link.STL" class="visual" />
        <body name="right_hip_roll_link" pos="0 -0.051265 -0.051265" quat="1.0 0.0 0.0 0.0">
          <joint name="right_hip_roll_joint" type="hinge" ref="0.0" class="motor" range="-0.785398 0.785398" axis="1 0 0" armature="0.100"/>
          <inertial pos="0.01525 0.0001796 -0.061059" quat="1.0 0.0 0.0 0.0" mass="0.83528" diaginertia="0.00054401 0.00063584 0.00038113" />
          <geom name="right_hip_roll_link_collision" pos="0 0 0" quat="1.0 0.0 0.0 0.0" type="mesh" mesh="right_hip_roll_link.STL" class="collision" />
          <geom name="right_hip_roll_link_visual" pos="0 0 0" quat="1.0 0.0 0.0 0.0"  type="mesh" mesh="right_hip_roll_link.STL" class="visual" />
          <body name="right_hip_yaw_link" pos="0 0 -0.09275" quat="1.0 0.0 0.0 0.0">
            <joint name="right_hip_yaw_joint" type="hinge" ref="0.0" class="motor" range="-0.785398 0.785398" axis="0 0 -1" armature="0.0343"/>
            <inertial pos="7.1067E-05 -0.00031339 -0.11496" quat="1.0 0.0 0.0 0.0" mass="1.2782" diaginertia="0.0024302 0.0025065 0.0007566" />
            <geom name="right_hip_yaw_link_collision" pos="0 0 0" quat="1.0 0.0 0.0 0.0" type="mesh" mesh="right_hip_yaw_link.STL" class="collision" />
            <geom name="right_hip_yaw_link_visual" pos="0 0 0" quat="1.0 0.0 0.0 0.0"  type="mesh" mesh="right_hip_yaw_link.STL" class="visual" />
            <body name="right_knee_link" pos="0 0 -0.15489" quat="1.0 0.0 0.0 0.0">
              <joint name="right_knee_joint" type="hinge" ref="0.0" class="motor" range="-1.5 0" axis="0 -1 0" armature="0.0330"/>
              <inertial pos="-0.0025213 -0.00051098 -0.10659" quat="1.0 0.0 0.0 0.0" mass="2.2481" diaginertia="0.0093796 0.0095623 0.0023403" />
              <geom name="right_knee_link_collision" pos="0 0 0" quat="1.0 0.0 0.0 0.0" type="mesh" mesh="right_knee_link.STL" class="collision" />
              <geom name="right_knee_link_visual" pos="0 0 0" quat="1.0 0.0 0.0 0.0"  type="mesh" mesh="right_knee_link.STL" class="visual" />
              <body name="right_ankle_pitch_link" pos="0 0 -0.29466" quat="1.0 0.0 0.0 0.0">
                <joint name="right_ankle_pitch_joint" type="hinge" ref="0.0" class="motor" range="-0.5 0.349066" axis="0 -1 0" armature="0.0236"/>
                <inertial pos="-0.0011784 5.9726E-08 -0.0061735" quat="1.0 0.0 0.0 0.0" mass="0.27369" diaginertia="6.4442e-05 8.1171e-05 4.7493e-05" />
                <geom name="right_ankle_pitch_link_collision" pos="0 0 0" quat="1.0 0.0 0.0 0.0" type="mesh" mesh="right_ankle_pitch_link.STL" class="collision" />
                <geom name="right_ankle_pitch_link_visual" pos="0 0 0" quat="1.0 0.0 0.0 0.0"  type="mesh" mesh="right_ankle_pitch_link.STL" class="visual" />
                <body name="right_ankle_roll_link" pos="-0.0015 0 -0.01" quat="1.0 0.0 0.0 0.0">
                  <joint name="right_ankle_roll_joint" type="hinge" ref="0.0" class="motor" range="-0.1 0.1" axis="-1 0 0" armature="0.0236"/>
                  <inertial pos="0.081347 0.00027474 -0.015509" quat="1.0 0.0 0.0 0.0" mass="0.61291" diaginertia="0.0003197 0.00045029 0.00070498" />
                  <geom name="right_ankle_roll_link_collision" pos="0 0 0" quat="1.0 0.0 0.0 0.0" type="mesh" mesh="right_ankle_roll_link.STL" class="collision" />
                  <geom name="right_ankle_roll_link_visual" pos="0 0 0" quat="1.0 0.0 0.0 0.0"  type="mesh" mesh="right_ankle_roll_link.STL" class="visual" />
                  <body name="right_toe_link" pos="0.10247 0.0042796 -0.0067324" quat="1.0 0.0 0.0 0.0">
                    <inertial pos="0.0320141754360937 -0.000816708013105544 -0.0141309094649689" quat="1.0 0.0 0.0 0.0" mass="0.112221754054884" diaginertia="5.5358948695321e-05 3.65052769951383e-05 8.54017357052965e-05" />
                    <geom name="right_toe_link_collision" pos="0 0 0" quat="1.0 0.0 0.0 0.0" type="mesh" mesh="right_toe_link.STL" class="collision" />
                    <geom name="right_toe_link_visual" pos="0 0 0" quat="1.0 0.0 0.0 0.0"  type="mesh" mesh="right_toe_link.STL" class="visual" />
                    <site name="right_foot" pos="0.04 0 -0.025"/>
                  </body>
                </body>
              </body>
            </body>
          </body>
        </body>
      </body>
      <site name="pelvis_link_site" pos="0 0 0" quat="1 0 0 0" />
      <camera name="front_camera" mode="track" fovy="90.0" quat="4.329780281177467e-17 4.329780281177466e-17 0.7071067811865475 0.7071067811865476" pos="0.0 2.0 0.5" />
      <camera name="side_camera" mode="track" fovy="90.0" quat="-0.5 -0.4999999999999999 0.5 0.5000000000000001" pos="-2.0 0.0 0.5" />
    </body>
  </worldbody>

  <actuator>
    <motor name="left_hip_pitch_joint_ctrl" joint="left_hip_pitch_joint" />
    <motor name="left_hip_roll_joint_ctrl" joint="left_hip_roll_joint"  />
    <motor name="left_hip_yaw_joint_ctrl" joint="left_hip_yaw_joint"  />
    <motor name="left_knee_joint_ctrl" joint="left_knee_joint"  />
    <motor name="left_ankle_pitch_joint_ctrl" joint="left_ankle_pitch_joint"  />
    <motor name="left_ankle_roll_joint_ctrl" joint="left_ankle_roll_joint"  />
    <motor name="right_hip_pitch_joint_ctrl" joint="right_hip_pitch_joint"  />
    <motor name="right_hip_roll_joint_ctrl" joint="right_hip_roll_joint"  />
    <motor name="right_hip_yaw_joint_ctrl" joint="right_hip_yaw_joint"  />
    <motor name="right_knee_joint_ctrl" joint="right_knee_joint"  />
    <motor name="right_ankle_pitch_joint_ctrl" joint="right_ankle_pitch_joint"  />
    <motor name="right_ankle_roll_joint_ctrl" joint="right_ankle_roll_joint"  />
  </actuator>

  <contact>
    <exclude body1="pelvis_link" body2="left_hip_pitch_link" />
    <exclude body1="left_hip_pitch_link" body2="left_hip_roll_link" />
    <exclude body1="left_hip_roll_link" body2="left_hip_yaw_link" />
    <exclude body1="left_hip_yaw_link" body2="left_knee_link" />
    <exclude body1="left_knee_link" body2="left_ankle_pitch_link" />
    <exclude body1="left_ankle_pitch_link" body2="left_ankle_roll_link" />
    <exclude body1="left_ankle_roll_link" body2="left_toe_link" />
    <exclude body1="pelvis_link" body2="right_hip_pitch_link" />
    <exclude body1="right_hip_pitch_link" body2="right_hip_roll_link" />
    <exclude body1="right_hip_roll_link" body2="right_hip_yaw_link" />
    <exclude body1="right_hip_yaw_link" body2="right_knee_link" />
    <exclude body1="right_knee_link" body2="right_ankle_pitch_link" />
    <exclude body1="right_ankle_pitch_link" body2="right_ankle_roll_link" />
    <exclude body1="right_ankle_roll_link" body2="right_toe_link" />
  </contact>




  <sensor>
    <gyro name="imu_ang_vel" site="imu_in_pelvis"/>
    <velocimeter name="imu_lin_vel" site="imu_in_pelvis"/>
    <framequat name="imu_quat" objtype="site" objname="imu_in_pelvis"/>
    <subtreeangmom name="root_angmom" body="pelvis_link"/>
  </sensor>

  <visual>
    <headlight diffuse="0.6 0.6 0.6" ambient="0.1 0.1 0.1" specular="0.9 0.9 0.9"/>
    <rgba haze="0.15 0.25 0.35 1"/>
    <global azimuth="-140" elevation="-20"/>
  </visual>


</mujoco>