<mujoco model="humanoid_pkg">
  <compiler angle="radian"/>

  <asset>
    <mesh name="base_link" content_type="model/stl" file="base_link.stl"/>
    <mesh name="torso_link" content_type="model/stl" file="torso_link.stl"/>
    <mesh name="waist_roll_link" content_type="model/stl" file="waist_roll_link.stl"/>
    <mesh name="waist_pitch_link" content_type="model/stl" file="waist_pitch_link.stl"/>
    <mesh name="chest_link" content_type="model/stl" file="chest_link.stl"/>
    <mesh name="left_shoulder_pitch_link" content_type="model/stl" file="left_shoulder_pitch_link.stl"/>
    <mesh name="left_shoulder_roll_link" content_type="model/stl" file="left_shoulder_roll_link.stl"/>
    <mesh name="left_elbow_yaw_link" content_type="model/stl" file="left_elbow_yaw_link.stl"/>
    <mesh name="left_elbow_forearm_yaw_link" content_type="model/stl" file="left_elbow_forearm_yaw_link.stl"/>
    <mesh name="left_wrist_yaw_link" content_type="model/stl" file="left_wrist_yaw_link.stl"/>
    <mesh name="right_shoulder_pitch_link" content_type="model/stl" file="right_shoulder_pitch_link.stl"/>
    <mesh name="right_shoulder_roll_link" content_type="model/stl" file="right_shoulder_roll_link.stl"/>
    <mesh name="right_elbow_yaw_link" content_type="model/stl" file="right_elbow_yaw_link.stl"/>
    <mesh name="right_elbow_forearm_yaw_link" content_type="model/stl" file="right_elbow_forearm_yaw_link.stl"/>
    <mesh name="right_wrist_yaw_link" content_type="model/stl" file="right_wrist_yaw_link.stl"/>
    <mesh name="neck_link" content_type="model/stl" file="neck_link.stl"/>
    <mesh name="neck_yaw_link" content_type="model/stl" file="neck_yaw_link.stl"/>
    <mesh name="head_link" content_type="model/stl" file="head_link.stl"/>
    <mesh name="camera_link" content_type="model/stl" file="camera_link.stl"/>
    <mesh name="waist_rod_link" content_type="model/stl" file="waist_rod_link.stl"/>
    <mesh name="right_hip_pitch_link" content_type="model/stl" file="right_hip_pitch_link.stl"/>
    <mesh name="right_hip_roll_link" content_type="model/stl" file="right_hip_roll_link.stl"/>
    <mesh name="right_hip_yaw_link" content_type="model/stl" file="right_hip_yaw_link.stl"/>
    <mesh name="right_knee_link" content_type="model/stl" file="right_knee_link.stl"/>
    <mesh name="right_foot1_link" content_type="model/stl" file="right_foot1_link.stl"/>
    <mesh name="right_foot2_link" content_type="model/stl" file="right_foot2_link.stl"/>
    <mesh name="right_ankle1_link" content_type="model/stl" file="right_ankle1_link.stl"/>
    <mesh name="right_ankle2_link" content_type="model/stl" file="right_ankle2_link.stl"/>
    <mesh name="left_hip_pitch_link" content_type="model/stl" file="left_hip_pitch_link.stl"/>
    <mesh name="left_hip_roll_link" content_type="model/stl" file="left_hip_roll_link.stl"/>
    <mesh name="left_hip_yaw_link" content_type="model/stl" file="left_hip_yaw_link.stl"/>
    <mesh name="left_knee_link" content_type="model/stl" file="left_knee_link.stl"/>
    <mesh name="left_foot1_link" content_type="model/stl" file="left_foot1_link.stl"/>
    <mesh name="left_foot2_link" content_type="model/stl" file="left_foot2_link.stl"/>
    <mesh name="left_ankle1_link" content_type="model/stl" file="left_ankle1_link.stl"/>
    <mesh name="left_ankle2_link" content_type="model/stl" file="left_ankle2_link.stl"/>
  </asset>

  <worldbody>
    <geom type="mesh" rgba="0.89804 0.91765 0.92941 1" mesh="base_link"/>
    <body name="torso_link" pos="2.08135e-05 -0.064 0.1123" quat="1 0 0 0.000162606">
      <inertial pos="0.00078123 -0.00026047 0.013243" quat="0.504721 0.503925 -0.495362 0.495916" mass="0.96233" diaginertia="0.000663059 0.000468721 0.00045115"/>
      <joint name="torso_joint" pos="0 0 0" axis="0 0 1" range="-3.14 3.14" actuatorfrcrange="-10 10"/>
      <geom type="mesh" rgba="0.79216 0.81961 0.93333 1" mesh="torso_link"/>
      <body name="waist_roll_link" pos="0 0 0.0616">
        <inertial pos="-3.1564e-09 3.1564e-09 0" quat="0.5 0.5 -0.5 0.5" mass="0.23579" diaginertia="9.0898e-05 5.1045e-05 5.1045e-05"/>
        <joint name="waist_roll_joint" pos="0 0 0" axis="1 0 0" range="-3.14 3.14" actuatorfrcrange="-10 10"/>
        <geom type="mesh" rgba="0.52941 0.54902 0.54902 1" mesh="waist_roll_link"/>
        <body name="waist_pitch_link" pos="0 -0.03 0">
          <inertial pos="0.00883777 0.0280342 0.162448" quat="0.758995 -0.0836902 -0.066749 0.642236" mass="2.69516" diaginertia="0.0353988 0.0276035 0.0144897"/>
          <joint name="waist_pitch_joint" pos="0 0 0" axis="0 1 0" range="-3.14 3.14" actuatorfrcrange="-10 10"/>
          <geom type="mesh" rgba="0.89804 0.91765 0.92941 1" mesh="waist_pitch_link"/>
          <geom pos="0.059 0.0299988 0.254964" quat="1 0 0 0" type="mesh" rgba="0.89804 0.91765 0.92941 1" mesh="chest_link"/>
          <geom pos="0 0.0299988 0.427514" quat="1 0 0 0" type="mesh" rgba="0.89804 0.91765 0.92941 1" mesh="neck_link"/>
          <body name="left_shoulder_pitch_link" pos="0 0.163919 0.341705">
            <inertial pos="0.00031467 -0.0041125 -0.0009434" quat="0.701298 0.0917136 -0.0929036 0.700813" mass="0.55787" diaginertia="0.000562495 0.00046536 0.000316025"/>
            <joint name="left_shoulder_pitch_joint" pos="0 0 0" axis="0 0.965926 0.258819" range="-3.14 3.14" actuatorfrcrange="-10 10"/>
            <geom type="mesh" rgba="0.79216 0.81961 0.93333 1" mesh="left_shoulder_pitch_link"/>
            <body name="left_shoulder_roll_link" pos="0.01965 0.064717 0.0173409">
              <inertial pos="-0.019316 0.00045538 -0.0075538" quat="0.41824 0.908328 0.00337416 0.00203267" mass="0.48965" diaginertia="0.000528752 0.000349197 0.000324481"/>
              <joint name="left_shoulder_roll_joint" pos="0 0 0" axis="-1 0 0" range="-3.14 3.14" actuatorfrcrange="-10 10"/>
              <geom type="mesh" rgba="0.79216 0.81961 0.93333 1" mesh="left_shoulder_roll_link"/>
              <body name="left_elbow_yaw_link" pos="-0.01965 0.0126821 -0.14058" quat="1 0 0 -0.000162606">
                <inertial pos="3.389e-05 -0.0037073 0.00016863" quat="0.705418 -0.0121492 0.0176214 0.708469" mass="0.24344" diaginertia="9.53696e-05 9.17654e-05 8.435e-05"/>
                <joint name="left_elbow_yaw_joint" pos="0 0 0" axis="0 0 1" range="-3.14 3.14" actuatorfrcrange="-10 10"/>
                <geom type="mesh" rgba="0.79216 0.81961 0.93333 1" mesh="left_elbow_yaw_link"/>
                <body name="left_elbow_forearm_yaw_link" pos="0 0.0265 -0.06825">
                  <inertial pos="4.0886e-05 -0.026352 -0.013654" quat="0.99995 0.00497269 0.000477013 0.00863926" mass="0.20469" diaginertia="8.412e-05 8.08155e-05 6.59355e-05"/>
                  <joint name="left_elbow_forearm_yaw_joint" pos="0 0 0" axis="0 -1 0" range="-3.14 3.14" actuatorfrcrange="-10 10"/>
                  <geom type="mesh" rgba="0.79216 0.81961 0.93333 1" mesh="left_elbow_forearm_yaw_link"/>
                  <body name="left_wrist_yaw_link" pos="2.7212e-05 -0.0261963 -0.1235">
                    <inertial pos="-0.0022153 -0.00030373 -0.017432" quat="0.999968 -0.00184374 -0.00778697 0.000773578" mass="0.3165" diaginertia="0.000131437 0.0001122 0.000103743"/>
                    <joint name="left_wrist_yaw_joint" pos="0 0 0" axis="0 0 -1" range="-3.14 3.14" actuatorfrcrange="-10 10"/>
                    <geom type="mesh" rgba="0.79216 0.81961 0.93333 1" mesh="left_wrist_yaw_link"/>
                  </body>
                </body>
              </body>
            </body>
          </body>
          <body name="right_shoulder_pitch_link" pos="0 -0.108459 0.342922">
            <inertial pos="0.00031467 0.0086652 -0.0021119" quat="0.700818 -0.0928695 0.0916842 0.701301" mass="0.55787" diaginertia="0.000562493 0.00046536 0.000316026"/>
            <joint name="right_shoulder_pitch_joint" pos="0 0 0" axis="0 -0.965926 0.258819" range="-3.14 3.14" actuatorfrcrange="-10 10"/>
            <geom type="mesh" rgba="0.79216 0.81961 0.93333 1" mesh="right_shoulder_pitch_link"/>
            <body name="right_shoulder_roll_link" pos="0.01965 -0.0601772 0.0161244">
              <inertial pos="-0.019338 -0.00043324 -0.007383" quat="0.90966 0.415333 -0.00213923 -0.00350991" mass="0.48888" diaginertia="0.000528423 0.000348694 0.000324022"/>
              <joint name="right_shoulder_roll_joint" pos="0 0 0" axis="-1 0 0" range="-3.14 3.14" actuatorfrcrange="-10 10"/>
              <geom type="mesh" rgba="0.79216 0.81961 0.93333 1" mesh="right_shoulder_roll_link"/>
              <body name="right_elbow_yaw_link" pos="-0.01965 -0.0126821 -0.14058">
                <inertial pos="-4.3563e-07 0.0037417 0.00016863" quat="0.708768 0.0128929 -0.0130141 0.705204" mass="0.24344" diaginertia="9.54129e-05 9.17169e-05 8.43552e-05"/>
                <joint name="right_elbow_yaw_joint" pos="0 0 0" axis="0 0 1" range="-3.14 3.14" actuatorfrcrange="-10 10"/>
                <geom type="mesh" rgba="0.79216 0.81961 0.93333 1" mesh="right_elbow_yaw_link"/>
                <body name="right_elbow_forearm_yaw_link" pos="0.000304331 0.02825 -0.0682696">
                  <inertial pos="-0.00034522 -0.028398 -0.013635" quat="0.99995 -0.00497269 -0.000477013 0.00863926" mass="0.20469" diaginertia="8.412e-05 8.08155e-05 6.59355e-05"/>
                  <joint name="right_elbow_forearm_yaw_joint" pos="0 0 0" axis="0 1 0" range="-3.14 3.14" actuatorfrcrange="-10 10"/>
                  <geom type="mesh" rgba="0.79216 0.81961 0.93333 1" mesh="right_elbow_forearm_yaw_link"/>
                  <body name="right_wrist_yaw_link" pos="-0.00053341 -0.0284513 -0.12348">
                    <inertial pos="-0.0019393 0.00024629 -0.017432" quat="0.999955 0.00363953 -0.00860247 0.00176806" mass="0.3165" diaginertia="0.000131448 0.00011219 0.000103741"/>
                    <joint name="right_wrist_yaw_joint" pos="0 0 0" axis="0 0 -1" range="-3.14 3.14" actuatorfrcrange="-10 10"/>
                    <geom type="mesh" rgba="0.79216 0.81961 0.93333 1" mesh="right_wrist_yaw_link"/>
                  </body>
                </body>
              </body>
            </body>
          </body>
          <body name="neck_yaw_link" pos="0 0.0299988 0.427514">
            <inertial pos="0.0026021 0.017715 0.019315" quat="0.890333 -0.296459 0.0624044 0.33989" mass="0.084323" diaginertia="2.56955e-05 2.39075e-05 1.6763e-05"/>
            <joint name="neck_yaw_joint" pos="0 0 0" axis="0 0 1" range="-3.14 3.14" actuatorfrcrange="-10 10"/>
            <geom type="mesh" rgba="0.89804 0.89804 0.89804 1" mesh="neck_yaw_link"/>
            <body name="head_link" pos="0.017615 0.0045 0.023005">
              <inertial pos="0.0295645 -0.0307825 0.0284958" quat="0.388017 0.921403 0.0168308 0.01328" mass="0.29662" diaginertia="0.00124419 0.000879133 0.000385635"/>
              <joint name="head_joint" pos="0 0 0" axis="0 1 0" range="-3.14 3.14" actuatorfrcrange="-10 10"/>
              <geom type="mesh" rgba="0.89804 0.91765 0.92941 1" mesh="head_link"/>
              <geom pos="0.045385 -0.0045 0.0774061" quat="1 0 0 0" type="mesh" rgba="0.89804 0.91765 0.92941 1" mesh="camera_link"/>
            </body>
          </body>
          <body name="waist_rod_link" pos="0 0.025 0.0561">
            <inertial pos="0.035116 0.005 -0.036408" quat="0.493233 0.493204 -0.506706 0.506675" mass="0.16381" diaginertia="7.50981e-05 4.87459e-05 4.5916e-05"/>
            <joint name="waist_rod_joint" pos="0 0 0" axis="0 -1 0" range="-3.14 3.14" actuatorfrcrange="-10 10"/>
            <geom type="mesh" rgba="0.89804 0.91765 0.92941 1" mesh="waist_rod_link"/>
          </body>
        </body>
      </body>
    </body>
    <body name="right_hip_pitch_link" pos="4.1627e-05 -0.128 0" quat="1 0 0 0.000162606">
      <inertial pos="-0.0076883 -0.03517 0.00056004" quat="0.992712 0.115309 -0.00964744 -0.0336693" mass="1.5469" diaginertia="0.00288375 0.00207107 0.00197607"/>
      <joint name="right_hip_pitch_joint" pos="0 0 0" axis="0 1 0" range="-3.14 3.14" actuatorfrcrange="-10 10"/>
      <geom type="mesh" rgba="0.79216 0.81961 0.93333 1" mesh="right_hip_pitch_link"/>
      <body name="right_hip_roll_link" pos="0.0202 -0.076 0">
        <inertial pos="-0.032145 -3.7396e-06 -0.063538" quat="0.999474 -7.01093e-07 -0.0324354 2.16037e-05" mass="0.7444" diaginertia="0.00155531 0.001194 0.000935294"/>
        <joint name="right_hip_roll_ joint" pos="0 0 0" axis="-1 0 0" range="-3.14 3.14" actuatorfrcrange="-10 10"/>
        <geom type="mesh" rgba="0.89804 0.91765 0.92941 1" mesh="right_hip_roll_link"/>
        <body name="right_hip_yaw_link" pos="-0.0202 0 -0.1757">
          <inertial pos="-2.7827e-05 -0.0016262 -0.02388" quat="0.501873 0.49827 0.501286 0.498561" mass="1.0856" diaginertia="0.00105081 0.000856782 0.00071265"/>
          <joint name="right_hip_yaw_joint" pos="0 0 0" axis="0 0 -1" range="-3.14 3.14" actuatorfrcrange="-10 10"/>
          <geom type="mesh" rgba="0.79216 0.81961 0.93333 1" mesh="right_hip_yaw_link"/>
          <body name="right_knee_link" pos="0 -0.0247 -0.1343">
            <inertial pos="0.00046937 0.027135 -0.098078" quat="0.999001 0.0446351 -0.000116938 0.00232482" mass="1.8135" diaginertia="0.008031 0.00798962 0.00131028"/>
            <joint name="right_knee_joint" pos="0 0 0" axis="0 1 0" range="-3.14 3.14" actuatorfrcrange="-10 10"/>
            <geom type="mesh" rgba="0.79216 0.81961 0.93333 1" mesh="right_knee_link"/>
            <body name="right_foot1_link" pos="0 0.297852 -0.318642" quat="0.999979 0.00648448 0 0">
              <inertial pos="3.1564e-09 -0.27313 0.0036841" quat="0.00458487 0.707092 0.00458487 0.707092" mass="0.23579" diaginertia="9.08977e-05 5.10453e-05 5.1045e-05"/>
              <joint name="right_foot1_joint" pos="0 0 0" axis="0 0.999916 -0.0129687" range="-3.14 3.14" actuatorfrcrange="-10 10"/>
              <geom type="mesh" rgba="0.52941 0.54902 0.54902 1" mesh="right_foot1_link"/>
              <body name="right_foot2_link" pos="-0.02 -0.273127 0.00368408" quat="0.999979 -0.00648448 0 0">
                <inertial pos="0.057171 -1.693e-09 -0.034065" quat="0 0.720938 0 0.693" mass="0.75781" diaginertia="0.00266586 0.002328 0.000446697"/>
                <joint name="right_foot2_joint" pos="0 0 0" axis="-1 0 0" range="-3.14 3.14" actuatorfrcrange="-10 10"/>
                <geom type="mesh" rgba="0.89804 0.91765 0.92941 1" mesh="right_foot2_link"/>
              </body>
            </body>
            <body name="right_ankle1_link" pos="0.0375 0.0247 -0.105">
              <inertial pos="0.0023931 0.017854 -0.048179" quat="0.999556 -0.0297259 -4.36764e-05 -0.00200704" mass="0.10199" diaginertia="0.00011992 0.00010589 1.52941e-05"/>
              <joint name="right_ankle1_joint" pos="0 0 0" axis="1 0 0" range="-3.14 3.14" actuatorfrcrange="-10 10"/>
              <geom type="mesh" rgba="0.64706 0.61961 0.58824 1" mesh="right_ankle1_link"/>
              <body name="right_ankle2_link" pos="0 0 -0.0645">
                <inertial pos="0.0012707 -0.016081 -0.027842" quat="0.998839 0.0481263 -3.98955e-05 0.0019853" mass="0.089313" diaginertia="4.96192e-05 3.55855e-05 1.50583e-05"/>
                <joint name="right_ankle2_joint" pos="0 0 0" axis="1 0 0" range="-3.14 3.14" actuatorfrcrange="-10 10"/>
                <geom type="mesh" rgba="0.64706 0.61961 0.58824 1" mesh="right_ankle2_link"/>
              </body>
            </body>
          </body>
        </body>
      </body>
    </body>
    <body name="left_hip_pitch_link">
      <inertial pos="-0.0076949 0.035164 -0.00056716" quat="0.992601 0.11621 0.00969005 0.0338305" mass="1.5469" diaginertia="0.00288379 0.00207112 0.00197599"/>
      <joint name="left_hip_pitch_joint" pos="0 0 0" axis="0.000325211 -1 0" range="-3.14 3.14" actuatorfrcrange="-10 10"/>
      <geom type="mesh" rgba="0.79216 0.81961 0.93333 1" mesh="left_hip_pitch_link"/>
      <body name="left_hip_roll_link" pos="0.0239754 0.075629 -0.000417045" quat="1 0 0 0.000162606">
        <inertial pos="-0.034577 0.0013532 -0.074963" quat="0.999252 0.00719015 -0.0379915 -0.000173782" mass="0.84068" diaginertia="0.00165655 0.00129023 0.00112671"/>
        <joint name="left_hip_roll_joint" pos="0 0 0" axis="-1 0 0" range="-3.14 3.14" actuatorfrcrange="-10 10"/>
        <geom type="mesh" rgba="0.89804 0.91765 0.92941 1" mesh="left_hip_roll_link"/>
        <body name="left_hip_yaw_link" pos="-0.024 0.00265744 -0.175268" quat="0.999979 0.00648448 0 0">
          <inertial pos="5.3998e-05 0.0016007 -0.02388" quat="0.498266 0.501877 0.498624 0.501222" mass="1.0856" diaginertia="0.00105081 0.000856783 0.00071265"/>
          <joint name="left_hip_yaw_joint" pos="0 0 0" axis="0 0 -1" range="-3.14 3.14" actuatorfrcrange="-10 10"/>
          <geom type="mesh" rgba="0.79216 0.81961 0.93333 1" mesh="left_hip_yaw_link"/>
          <body name="left_knee_link" pos="0.000417045 0.0285 -0.133921">
            <inertial pos="5.5858e-05 -0.030933 -0.098447" quat="0.999001 -0.0446328 -0.000101463 -0.00212519" mass="1.8134" diaginertia="0.0080308 0.00798941 0.00131028"/>
            <joint name="left_knee_joint" pos="0 0 0" axis="0 -1 0" range="-3.14 3.14" actuatorfrcrange="-10 10"/>
            <geom type="mesh" rgba="0.89804 0.91765 0.92941 1" mesh="left_knee_link"/>
            <body name="left_foot1_link" pos="-0.000417045 -0.0435 -0.318879">
              <inertial pos="-3.1564e-09 0.015 0" quat="0.5 0.5 -0.5 0.5" mass="0.23579" diaginertia="9.0898e-05 5.1045e-05 5.1045e-05"/>
              <joint name="left_foot1_joint" pos="0 0 0" axis="0 1 0" range="-3.14 3.14" actuatorfrcrange="-10 10"/>
              <geom type="mesh" rgba="0.52941 0.54902 0.54902 1" mesh="left_foot1_link"/>
              <body name="left_foot2_link" pos="-0.02 0.015 0">
                <inertial pos="0.057204 -0.00036388 -0.033983" quat="0.00465825 0.720924 0.00447622 0.692984" mass="0.76036" diaginertia="0.00266592 0.00232824 0.000447017"/>
                <joint name="left_foot2_joint" pos="0 0 0" axis="-1 0 0" range="-3.14 3.14" actuatorfrcrange="-10 10"/>
                <geom type="mesh" rgba="0.79216 0.81961 0.93333 1" mesh="left_foot2_link"/>
              </body>
            </body>
            <body name="left_ankle1_link" pos="0.034083 -0.0285 -0.105379">
              <inertial pos="0.0053547 -0.017758 -0.048415" quat="0.99961 0.0278516 -4.82163e-05 0.00198332" mass="0.1027" diaginertia="0.00011993 0.000105871 1.53253e-05"/>
              <joint name="left_ankle1_joint" pos="0 0 0" axis="1 0 0" range="-3.14 3.14" actuatorfrcrange="-10 10"/>
              <geom type="mesh" rgba="0.64706 0.61961 0.58824 1" mesh="left_ankle1_link"/>
              <body name="left_ankle2_link" pos="0 0 -0.0645">
                <inertial pos="0.0042648 0.016034 -0.027953" quat="0.998886 -0.0471512 -4.84159e-05 -0.00202925" mass="0.089431" diaginertia="4.96192e-05 3.55788e-05 1.5068e-05"/>
                <joint name="left_ankle2_joint" pos="0 0 0" axis="1 0 0" range="-3.14 3.14" actuatorfrcrange="-10 10"/>
                <geom type="mesh" rgba="0.89804 0.91765 0.92941 1" mesh="left_ankle2_link"/>
              </body>
            </body>
          </body>
        </body>
      </body>
    </body>
  </worldbody>
</mujoco>
